/some/path/to/runPipeline.ts:XX
           return new ContextualError(message, {
                  ^

ContextualError: There was an error in the interceptor "anonymous" (use named functions to improve this error message) while running hook "exchange".
    at runPipeline (/some/path/to/runPipeline.ts:XX:XX)
    at async runPipeline (/some/path/to/runPipeline.ts:XX:XX)
    at async runPipeline (/some/path/to/runPipeline.ts:XX:XX)
    at async <anonymous> (/some/path/to/runner.ts:XX:XX)
    at async Module.run (/some/path/to/run.ts:XX:XX)
    at async sendRequest (/some/path/to/send.ts:XX:XX)
    at async <anonymous> (/some/path/to/output_preset__standard-graphql.ts:XX:XX) {
  context: {
    hookName: 'exchange',
    source: 'extension',
    interceptorName: 'anonymous'
  },
  cause: TypeError: Invalid URL
      at new URL (node:internal/url:XX:XX)
      at <anonymous> (/some/path/to/output_preset__standard-graphql.ts:XX:XX)
      at applyBody (/some/path/to/runner.ts:XX:XX) {
    code: 'ERR_INVALID_URL',
    input: 'bad'
  }
}

Node.js vXX.XX.XX